Workbook

Sheet Question 1
B2: Dependency Table
B3: Instruction address | C3: ID | D3: Instruction | E3: Latency | F3: Destination register | G3: True dependencies | K3: False dependencies
G4: Local | H4: Interloop | I4: Loop Invariant | J4: Post Loop | K4: Anti dependency | L4: Output dependency
B5: 0 | C5: A | D5: mov LC, 16 | E5: 1 | F5: LC | G5: - | H5: - | I5: - | J5: - | K5: - | L5: -
B6: 1 | C6: B | D6: mov x2, 0x1000 | E6: 1 | F6: x2 | G6: - | H6: - | I6: - | J6: - | K6: - | L6: -
B7: 2 | C7: C | D7: mov x3, 0x2000 | E7: 1 | F7: x3 | G7: - | H7: - | I7: - | J7: - | K7: - | L7: -
B8: 3 | C8: D | D8: ld x4, 0(x2) | E8: 2 | F8: x4 | G8: - | H8: x2 : (B, H') | I8: - | J8: - | K8: - | L8: -
B9: 4 | C9: E | D9: ld x5, 1(x2) | E9: 2 | F9: x5 | G9: - | H9: x2 : (B, H') | I9: - | J9: - | K9: - | L9: -
B10: 5 | C10: F | D10: add x6, x4, x5 | E10: 2 | F10: x6 | G10: x4 : D / x5 : E | H10: - | I10: - | J10: - | K10: x6 : G' | L10: -
B11: 6 | C11: G | D11: st x6, 0(x3) | E11: 2 | F11: - | G11: x6 : F | H11: x3 : (C, I') | I11: - | J11: - | K11: - | L11: -
B12: 7 | C12: H | D12: addi x2, x2, 1 | E12: 2 | F12: x2 | G12: - | H12: x2 : (B, H') | I12: - | J12: - | K12: - | L12: -
B13: 8 | C13: I | D13: addi x3, x3, 1 | E13: 2 | F13: x3 | G13: - | H13: x3 : (C, I') | I13: - | J13: - | K13: - | L13: -
B14: 9 | C14: J | D14: loop 3 | E14: 1 | F14: LC | G14: - | H14: LC : (A, J') | I14: - | J14: - | K14: - | L14: -
B15: 10 | C15: K | D15: mov x7, 0x2000 | E15: 1 | F15: x7 | G15: - | H15: - | I15: - | J15: - | K15: - | L15: -
B16: 11 | C16: L | D16: ld x2, 0(x3) | E16: 2 | F16: x2 | G16: - | H16: - | I16: - | J16: x3 : I | K16: - | L16: x2 : H
... B19: 14 | C19: O | D19: st x6, 0(x3) | E19: 2 | F19: - | G19: x6 : N | H19: - | I19: - | J19: x3 : I | K19: - | L19: -

Sheet Question 2
B2: Static scheduling without register renaming (no pipeline) | H2: ID | I2: Instruction | J2: Latency
C3: ALU 1 | D3: ALU 2 | E3: Memory Unit | F3: Branch Unit | H3: A | I3: mov LC, 16 | J3: 1
B4: 0 | C4: A | D4: B | E4: nop | F4: nop | H4: B | I4: mov x2, 0x1000 | J4: 1
B5: 1 | C5: C | D5: nop | E5: nop | F5: nop | H5: C | I5: mov x3, 0x2000 | J5: 1
B6: 2 | C6: H | D6: I | E6: D | F6: nop | H6: D | I6: ld x4, 0(x2) | J6: 2
B7: 3 | C7: nop | D7: nop | E7: E | F7: nop | H7: E | I7: ld x5, 1(x2) | J7: 2
B8: 4 | C8: nop | D8: nop | E8: nop | F8: nop | H8: F | I8: add x6, x4, x5 | J8: 2
B9: 5 | C9: F | D9: nop | E9: nop | F9: nop | H9: G | I9: st x6, 0(x3) | J9: 2
B10: 6 | C10: nop | D10: nop | E10: nop | F10: nop | H10: H | I10: addi x2, x2, 1 | J10: 2
B11: 7 | C11: nop | D11: nop | E11: G | F11: J : loop 2 | H11: I | I11: addi x3, x3, 1 | J11: 2
B12: 8 | C12: K | D12: nop | E12: L | F12: nop | H12: J | I12: loop 3 | J12: 1
B13: 9 | C13: nop | D13: nop | E13: M | F13: nop | H13: K | I13: mov x7, 0x2000 | J13: 1
B14: 10 | C14: nop | D14: nop | E14: nop | F14: nop | H14: L | I14: ld x2, 0(x3) | J14: 2
B15: 11 | C15: N | D15: nop | E15: nop | F15: nop | H15: M | I15: ld x4, 0(x7) | J15: 2
... B17: 13 | C17: nop | D17: nop | E17: O | F17: nop | H17: O | I17: st x6, 0(x3) | J17: 2

Sheet Question 3
B2: ID | C2: Old Instruction | D2: Old Destination Register | E2: New Destination Register | F2: New Instruction
B3: A | C3: mov LC, 16 | D3: LC | E3: LC | F3: mov LC, 16
B4: B | C4: mov x2, 0x1000 | D4: x2 | E4: x1 | F4: mov x1, 0x1000
B5: C | C5: mov x3, 0x2000 | D5: x3 | E5: x2 | F5: mov x2, 0x2000
B6: D | C6: ld x4, 0(x2) | D6: x4 | E6: x3 | F6: ld x3, 0(x1)
B7: E | C7: ld x5, 1(x2) | D7: x5 | E7: x4 | F7: ld x4, 1(x1)
B8: F | C8: add x6, x4, x5 | D8: x6 | E8: x5 | F8: add x5, x3, x4
B9: G | C9: st x6, 0(x3) | D9: - | E9: - | F9: st x5, 0(x2)
B10: H | C10: addi x2, x2, 1 | D10: x2 | E10: x6 | F10: addi x6, x1, 1
B11: I | C11: addi x3, x3, 1 | D11: x3 | E11: x7 | F11: addi x7, x2, 1
B12: J | C12: loop 3 | D12: LC | E12: LC | F12: loop 3
B13: K | C13: mov x7, 0x2000 | D13: x7 | E13: x8 | F13: mov x8, 0x2000
... B17: O | C17: st x6, 0(x3) | D17: - | E17: - | F17: st x11, 0(x7)
B19: ID | C19: Instructions to add before J
B20: Y | C20: mov x1, x6
B21: Z | C21: mov x2, x7
B23: ID | C23: Destination Register | D23: True dependency
D24: Local | E24: Interloop | F24: Loop Invariant | G24: Post Loop
B25: A | C25: LC | D25: - | E25: - | F25: - | G25: -
B26: B | C26: =E4 -> x1 | D26: - | E26: - | F26: - | G26: -
B27: C | C27: =E5 -> x2 | D27: - | E27: - | F27: - | G27: -
B28: D | C28: =E6 -> x3 | D28: - | E28: x1 : (B, Y') | F28: - | G28: -
B29: E | C29: =E7 -> x4 | D29: - | E29: x1 : (B, Y') | F29: - | G29: -
B30: F | C30: =E8 -> x5 | D30: x3 : D / x4 : E | E30: - | F30: - | G30: -
B31: G | C31: =E9 -> - | D31: x5 : F | E31: x2 : (C, Z') | F31: - | G31: -
B32: H | C32: =E10 -> x6 | D32: - | E32: x1 : (B, Y') | F32: - | G32: -
B33: I | C33: =E11 -> x7 | D33: - | E33: x2 : (C, Z') | F33: - | G33: -
B34: Y | C34: x1 | D34: x6 : H | E34: - | F34: - | G34: -
B35: Z | C35: x2 | D35: x7 : I | E35: - | F35: - | G35: -
B36: J | C36: =E12 -> LC | D36: - | E36: LC : (A, J') | F36: - | G36: -
B37: K | C37: =E13 -> x8 | D37: - | E37: - | F37: - | G37: -
B38: L | C38: =E14 -> x9 | D38: - | E38: - | F38: - | G38: x7 : I
B39: M | C39: =E15 -> x10 | D39: x8 : K | E39: - | F39: - | G39: -
B40: N | C40: =E16 -> x11 | D40: x9 : L / x10 : M | E40: - | F40: - | G40: -
B41: O | C41: =E17 -> - | D41: x11 : N | E41: - | F41: - | G41: x7 : I
B43: Static scheduling with register renaming (no loop pipelining)
C44: ALU 1 | D44: ALU 2 | E44: Memory Unit | F44: Branch Unit
B45: 0 | C45: A | D45: B | E45: nop | F45: nop
B46: 1 | C46: C | D46: nop | E46: nop | F46: nop
B47: 2 | C47: H | D47: I | E47: D | F47: nop
...

Sheet Question 4
B2: Units | C2: ALU | D2: Memory | E2: Branch | J2: ID | K2: Instruction
B3: N | C3: 3 | D3: 3 | E3: 1 | J3: A | K3: mov LC, 16
B4: U | C4: 2 | D4: 1 | E4: 1 | G4: Initialisation Interval | H4: =MAX(C5:E5) -> 3 | J4: B | K4: mov x2, 0x1000
B5: N/U | C5: =ROUNDUP(C3/C4, 0) -> 2 | D5: =ROUNDUP(D3/D4, 0) -> 3 | E5: =ROUNDUP(E3/E4, 0) -> 1 | J5: C | K5: mov x3, 0x2000
J6: D | K6: ld x4, 0(x2)
J7: E | K7: ld x5, 1(x2)
J8: F | K8: add x6, x4, x5
J9: G | K9: st x6, 0(x3)
J10: H | K10: addi x2, x2, 1
J11: I | K11: addi x3, x3, 1
J12: J | K12: loop 3
J13: K | K13: mov x7, 0x2000
J14: L | K14: ld x2, 0(x3)
J15: M | K15: ld x4, 0(x7)
J16: N | K16: add x6, x2, x4
J17: O | K17: st x6, 0(x3)

Sheet Question 5
B2: Pipelined static schedule without register renaming | I2: ID | J2: Instruction
C3: ALU 1 | D3: ALU 2 | E3: Memory Unit | F3: Branch Unit | G3: Stage | I3: A | J3: mov LC, 16
B4: 0 | C4: A | D4: B | E4: nop | F4: nop | G4: - | I4: B | J4: mov x2, 0x1000
B5: 1 | C5: C | D5: nop | E5: nop | F5: nop | G5: - | I5: C | J5: mov x3, 0x2000
B6: 2 | C6: -- | D6: H | E6: D | F6: nop | G6: 0 | I6: D | J6: ld x4, 0(x2)
B7: 3 | C7: I | D7: nop | E7: E | F7: nop | G7: 0 | I7: E | J7: ld x5, 1(x2)
B8: 4 | C8: nop | D8: nop | E8: -- | F8: J : loop 2 | G8: 0 | I8: F | J8: add x6, x4, x5
B9: 5 | C9: F | D9: -- | E9: -- | F9: nop | G9: 1 | I9: G | J9: st x6, 0(x3)
B10: 6 | C10: -- | D10: nop | E10: -- | F10: nop | G10: 1 | I10: H | J10: addi x2, x2, 1
B11: 7 | C11: nop | D11: nop | E11: G | F11: -- | G11: 1 | I11: I | J11: addi x3, x3, 1
B12: 10 | C12: K | D12: nop | E12: L | F12: nop | G12: - | I12: J | J12: loop 3
B13: 11 | C13: nop | D13: nop | E13: M | F13: nop | G13: - | I13: K | J13: mov x7, 0x2000
B14: 12 | C14: nop | D14: nop | E14: nop | F14: nop | G14: - | I14: L | J14: ld x2, 0(x3)
B15: 13 | C15: N | D15: nop | E15: nop | F15: nop | G15: - | I15: M | J15: ld x4, 0(x7)
B16: 14 | C16: nop | D16: nop | E16: nop | F16: nop | G16: - | I16: N | J16: add x6, x2, x4
B17: 15 | C17: nop | D17: nop | E17: O | F17: nop | G17: - | I17: O | J17: st x6, 0(x3)

Sheet Question 6
B2: Loop instructions with a destination register
B3: ID | C3: Old Instruction | D3: Old Destination Register | E3: Base Rotating Register
B4: D | C4: ld x4, 0(x2) | D4: x4 | E4: x32
B5: E | C5: ld x5, 1(x2) | D5: x5 | E5: x35
B6: F | C6: add x6, x4, x5 | D6: x6 | E6: x38
B7: H | C7: addi x2, x2, 1 | D7: x2 | E7: x41
B8: I | C8: addi x3, x3, 1 | D8: x3 | E8: x44
B10: Other instructions with different destination registers
B11: ID | C11: Old Instruction | D11: Old Destination Register | E11: New Destination Register
B12: K | C12: mov x7, 0x2000 | D12: x7 | E12: x1
B13: L | C13: ld x2, 0(x3) | D13: x2 | E13: x2
B14: M | C14: ld x4, 0(x7) | D14: x4 | E14: x3
B15: N | C15: add x6, x2, x4 | D15: x6 | E15: x4
B17: ID | C17: Old Instruction | D17: New Instruction | G17: (Question 5) Pipelined static schedule without register renaming
B18: A | C18: mov LC, 16 | D18: mov LC, 16 | H18: ALU 1 | I18: ALU 2 | J18: Memory Unit | K18: Branch Unit | L18: Stage
B19: B | C19: mov x2, 0x1000 | D19: mov x41(+1, +0), 0x1000 | G19: 0 | H19: ='Question 5'!C4 -> A | I19: ='Question 5'!D4 -> B | J19: ='Question 5'!E4 -> nop | K19: ='Question 5'!F4 -> nop | L19: -
B20: C | C20: mov x3, 0x2000 | D20: mov x44(+1, +0), 0x2000 | G20: 1 | H20: ='Question 5'!C5 -> C | I20: ='Question 5'!D5 -> nop | J20: ='Question 5'!E5 -> nop | K20: ='Question 5'!F5 -> nop | L20: -
B21: D | C21: ld x4, 0(x2) | D21: ld x32, 0(x41(+1, +0)) | G21: 2 | H21: ='Question 5'!C6 -> -- | I21: ='Question 5'!D6 -> H | J21: ='Question 5'!E6 -> D | K21: ='Question 5'!F6 -> nop | L21: ='Question 5'!G6 -> 0
B22: E | C22: ld x5, 1(x2) | D22: ld x35, 1(x41(+1, +0)) | G22: 3 | H22: ='Question 5'!C7 -> I | I22: ='Question 5'!D7 -> nop | J22: ='Question 5'!E7 -> E | K22: ='Question 5'!F7 -> nop | L22: ='Question 5'!G7 -> 0
B23: F | C23: add x6, x4, x5 | D23: add x38, x32(+0, +1), x35(+0, +1) | G23: 4 | H23: ='Question 5'!C8 -> nop | I23: ='Question 5'!D8 -> nop | J23: ='Question 5'!E8 -> -- | K23: ='Question 5'!F8 -> J : loop 2 | L23: ='Question 5'!G8 -> 0
B24: G | C24: st x6, 0(x3) | D24: st x38(+0, +0), 0(x44(+1, +1)) | G24: 5 | H24: ='Question 5'!C9 -> F | I24: ='Question 5'!D9 -> -- | J24: ='Question 5'!E9 -> -- | K24: ='Question 5'!F9 -> nop | L24: ='Question 5'!G9 -> 1
B25: H | C25: addi x2, x2, 1 | D25: addi x41, x41(+1, +0), 1 | G25: 6 | H25: ='Question 5'!C10 -> -- | I25: ='Question 5'!D10 -> nop | J25: ='Question 5'!E10 -> -- | K25: ='Question 5'!F10 -> nop | L25: ='Question 5'!G10 -> 1
B26: I | C26: addi x3, x3, 1 | D26: addi x44, x44(+1, +0), 1 | G26: 7 | H26: ='Question 5'!C11 -> nop | I26: ='Question 5'!D11 -> nop | J26: ='Question 5'!E11 -> G | K26: ='Question 5'!F11 -> -- | L26: ='Question 5'!G11 -> 1
B27: J | C27: loop 3 | D27: loop 2 | G27: 10 | H27: ='Question 5'!C12 -> K | I27: ='Question 5'!D12 -> nop | J27: ='Question 5'!E12 -> L | K27: ='Question 5'!F12 -> nop | L27: -
B28: K | C28: mov x7, 0x2000 | D28: mov x1, 0x2000 | G28: 11 | H28: ='Question 5'!C13 -> nop | I28: ='Question 5'!D13 -> nop | J28: ='Question 5'!E13 -> M | K28: ='Question 5'!F13 -> nop | L28: -
B29: L | C29: ld x2, 0(x3) | D29: ld x2, 0(x44(+0, +1)) | G29: 12 | H29: ='Question 5'!C14 -> nop | I29: ='Question 5'!D14 -> nop | J29: ='Question 5'!E14 -> nop | K29: ='Question 5'!F14 -> nop | L29: -
B30: M | C30: ld x4, 0(x7) | D30: ld x3, 0(x1) | G30: 13 | H30: ='Question 5'!C15 -> N | I30: ='Question 5'!D15 -> nop | J30: ='Question 5'!E15 -> nop | K30: ='Question 5'!F15 -> nop | L30: -
B31: N | C31: add x6, x2, x4 | D31: add x4, x2, x3 | G31: 14 | H31: ='Question 5'!C16 -> nop | I31: ='Question 5'!D16 -> nop | J31: ='Question 5'!E16 -> nop | K31: ='Question 5'!F16 -> nop | L31: -
B32: O | C32: st x6, 0(x3) | D32: st x4, 0(x44(+0, +1)) | G32: 15 | H32: ='Question 5'!C17 -> nop | I32: ='Question 5'!D17 -> nop | J32: ='Question 5'!E17 -> O | K32: ='Question 5'!F17 -> nop | L32: -
B34: Pipelined static schedule with register renaming
C35: ALU 1 | D35: ALU 2 | E35: Memory Unit | F35: Branch Unit | G35: Stage
B36: 0 | C36: mov LC, 16 | D36: mov x42, 0x1000 | E36: nop | F36: nop | G36: -
B37: 1 | C37: mov x45, 0x2000 | D37: nop | E37: nop | F37: nop | G37: -
B38: 2 | C38: -- | D38: addi x41, x42, 1 | E38: ld x32, 0(x42) | F38: nop | G38: 0
B39: 3 | C39: addi x44, x45, 1 | D39: nop | E39: ld x35, 1(x42) | F39: nop | G39: 0
B40: 4 | C40: nop | D40: nop | E40: -- | F40: J : loop 2 | G40: 0
B41: 5 | C41: add x38, x33, x36 | D41: -- | E41: -- | F41: nop | G41: 1
B42: 6 | C42: -- | D42: nop | E42: -- | F42: nop | G42: 1
B43: 7 | C43: nop | D43: nop | E43: st x38, 0(x46) | F43: -- | G43: 1
B44: 10 | C44: mov x1, 0x2000 | D44: nop | E44: ld x2, 0(x45) | F44: nop | G44: -
...
